import { describe, it, expect, vi } from 'vitest'
import { render, screen } from '../../../test/utils'
import { ErrorBoundary } from '../ErrorBoundary'

// Component that throws an error for testing
const ThrowError = ({ shouldThrow }: { shouldThrow: boolean }) => {
  if (shouldThrow) {
    throw new Error('Test error')
  }
  return <div>No error</div>
}

describe('ErrorBoundary', () => {
  // Suppress console.error for these tests
  const originalError = console.error
  beforeAll(() => {
    console.error = vi.fn()
  })
  
  afterAll(() => {
    console.error = originalError
  })

  it('renders children when there is no error', () => {
    render(
      <ErrorBoundary>
        <ThrowError shouldThrow={false} />
      </ErrorBoundary>
    )
    
    expect(screen.getByText('No error')).toBeInTheDocument()
  })

  it('renders error UI when there is an error', () => {
    render(
      <ErrorBoundary>
        <ThrowError shouldThrow={true} />
      </ErrorBoundary>
    )
    
    expect(screen.getByText(/something went wrong/i)).toBeInTheDocument()
    expect(screen.getByText(/test error/i)).toBeInTheDocument()
  })

  it('renders custom fallback when provided', () => {
    const customFallback = <div>Custom error message</div>
    
    render(
      <ErrorBoundary fallback={customFallback}>
        <ThrowError shouldThrow={true} />
      </ErrorBoundary>
    )
    
    expect(screen.getByText('Custom error message')).toBeInTheDocument()
  })

  it('calls onError callback when error occurs', () => {
    const onError = vi.fn()
    
    render(
      <ErrorBoundary onError={onError}>
        <ThrowError shouldThrow={true} />
      </ErrorBoundary>
    )
    
    expect(onError).toHaveBeenCalledWith(
      expect.any(Error),
      expect.objectContaining({
        componentStack: expect.any(String)
      })
    )
  })

  it('has retry functionality', async () => {
    const { rerender } = render(
      <ErrorBoundary>
        <ThrowError shouldThrow={true} />
      </ErrorBoundary>
    )
    
    expect(screen.getByText(/something went wrong/i)).toBeInTheDocument()
    
    const retryButton = screen.getByRole('button', { name: /try again/i })
    expect(retryButton).toBeInTheDocument()
    
    // Simulate fixing the error and retrying
    rerender(
      <ErrorBoundary>
        <ThrowError shouldThrow={false} />
      </ErrorBoundary>
    )
    
    retryButton.click()
    
    expect(screen.getByText('No error')).toBeInTheDocument()
  })
})